<mujoco model="pusht">
  <option timestep="0.01" iterations="1" ls_iterations="4" />

  <default>
    <velocity ctrllimited="true" ctrlrange="-1.0 1.0" kv="0.1"/>
    <geom friction="1.0" solimp="0.0 0.95 0.005" solref="0.02 1"/>
  </default>

  <worldbody>
    <body name="point_mass" pos="0 0 .011">
      <joint name="root_x" type="slide" pos="0 0 0" axis="1 0 0" />
      <joint name="root_y" type="slide" pos="0 0 0" axis="0 1 0" />
      <geom name="point_mass" type="sphere" size=".01" rgba="0 1 0 1" />
    </body>
  </worldbody>

  <actuator>
    <velocity name="x_motor" joint="root_x" />
    <velocity name="y_motor" joint="root_y" />
  </actuator>

</mujoco>
